<?xml version="1.0" encoding="utf-8"?>
<!-- This URDF was automatically created by SolidWorks to URDF Exporter! Originally created by Stephen Brawner (brawner@gmail.com) 
     Commit Version: 1.6.0-4-g7f85cfe  Build Version: 1.6.7995.38578
     For more information, please see http://wiki.ros.org/sw_urdf_exporter -->
<robot
  name="Ros2_RobotBipede">
  <link
    name="base_link">
    <inertial>
      <origin
        xyz="-0.020266479508749 0.00111490010484205 0.0742713043923713"
        rpy="0 0 0" />
      <mass
        value="6.15060830667613" />
      <inertia
        ixx="0.0669131459127444"
        ixy="0.000331095916278806"
        ixz="-0.000546305633000038"
        iyy="0.0729062050878231"
        iyz="3.03791421785394E-05"
        izz="0.105752689810875" />
    </inertial>
    <visual>
      <origin
        xyz="0 0 0"
        rpy="0 0 0" />
      <geometry>
        <mesh
          filename="package://Ros2_RobotBipede/meshes/base_link.STL" />
      </geometry>
      <material
        name="">
        <color
          rgba="0.792156862745098 0.819607843137255 0.933333333333333 1" />
      </material>
    </visual>
    <collision>
      <origin
        xyz="0 0 0"
        rpy="0 0 0" />
      <geometry>
        <mesh
          filename="package://Ros2_RobotBipede/meshes/base_link.STL" />
      </geometry>
    </collision>
  </link>
  <link
    name="Link_HipYaw_D">
    <inertial>
      <origin
        xyz="-0.000950446172793551 -0.022867540621532 0.0751667640877387"
        rpy="0 0 0" />
      <mass
        value="0.950205196869861" />
      <inertia
        ixx="0.000888214151991332"
        ixy="1.7502257146007E-05"
        ixz="-1.39606253666135E-06"
        iyy="0.00130742972960493"
        iyz="-1.83060478020218E-05"
        izz="0.000919916632233785" />
    </inertial>
    <visual>
      <origin
        xyz="0 0 0"
        rpy="0 0 0" />
      <geometry>
        <mesh
          filename="package://Ros2_RobotBipede/meshes/Link_HipYaw_D.STL" />
      </geometry>
      <material
        name="">
        <color
          rgba="0.792156862745098 0.819607843137255 0.933333333333333 1" />
      </material>
    </visual>
    <collision>
      <origin
        xyz="0 0 0"
        rpy="0 0 0" />
      <geometry>
        <mesh
          filename="package://Ros2_RobotBipede/meshes/Link_HipYaw_D.STL" />
      </geometry>
    </collision>
  </link>
  <joint
    name="Joint_HipYaw_D"
    type="revolute">
    <origin
      xyz="-0.018147 -0.056077 0.1075"
      rpy="0 0 0" />
    <parent
      link="base_link" />
    <child
      link="Link_HipYaw_D" />
    <axis
      xyz="0 0 1" />
    <limit
      lower="-0.5236"
      upper="0.5236"
      effort="0"
      velocity="0" />
    <safety_controller
      k_position="1"
      k_velocity="1" />
  </joint>
  <link
    name="Link_HipPitch_D">
    <inertial>
      <origin
        xyz="-6.8761873466272E-06 0.00114519719993722 0.457300281508992"
        rpy="0 0 0" />
      <mass
        value="1.95580532271771" />
      <inertia
        ixx="0.00182757562838347"
        ixy="0.000179492807069441"
        ixz="-0.001095412325116"
        iyy="0.0114156387635016"
        iyz="3.81005450736091E-05"
        izz="0.012498153302823" />
    </inertial>
    <visual>
      <origin
        xyz="0 0 0"
        rpy="0 0 0" />
      <geometry>
        <mesh
          filename="package://Ros2_RobotBipede/meshes/Link_HipPitch_D.STL" />
      </geometry>
      <material
        name="">
        <color
          rgba="0.792156862745098 0.819607843137255 0.933333333333333 1" />
      </material>
    </visual>
    <collision>
      <origin
        xyz="0 0 0"
        rpy="0 0 0" />
      <geometry>
        <mesh
          filename="package://Ros2_RobotBipede/meshes/Link_HipPitch_D.STL" />
      </geometry>
    </collision>
  </link>
  <joint
    name="Joint_HipPitch_D"
    type="revolute">
    <origin
      xyz="0.016242 0.29906 0.078"
      rpy="1.5708 1.536 -0.0534" />
    <parent
      link="Link_HipYaw_D" />
    <child
      link="Link_HipPitch_D" />
    <axis
      xyz="0 0 -1" />
    <limit
      lower="-1.5707"
      upper="0"
      effort="0"
      velocity="0" />
  </joint>
  <link
    name="Link_Knee_D">
    <inertial>
      <origin
        xyz="0.1361476135622 0.0145881522897291 0.5193145230582"
        rpy="0 0 0" />
      <mass
        value="0.315635651588114" />
      <inertia
        ixx="0.000254426443966662"
        ixy="-0.000351345947960491"
        ixz="0.000315168780030322"
        iyy="0.00309252932985989"
        iyz="3.9094254157864E-05"
        izz="0.00316186302023711" />
    </inertial>
    <visual>
      <origin
        xyz="0 0 0"
        rpy="0 0 0" />
      <geometry>
        <mesh
          filename="package://Ros2_RobotBipede/meshes/Link_Knee_D.STL" />
      </geometry>
      <material
        name="">
        <color
          rgba="0 1 1 1" />
      </material>
    </visual>
    <collision>
      <origin
        xyz="0 0 0"
        rpy="0 0 0" />
      <geometry>
        <mesh
          filename="package://Ros2_RobotBipede/meshes/Link_Knee_D.STL" />
      </geometry>
    </collision>
  </link>
  <joint
    name="Joint_Knee_D"
    type="revolute">
    <origin
      xyz="0.16 0 -0.0245"
      rpy="0 0 -0.19569" />
    <parent
      link="Link_HipPitch_D" />
    <child
      link="Link_Knee_D" />
    <axis
      xyz="0 0 -1" />
    <limit
      lower="0"
      upper="3.1415"
      effort="0"
      velocity="0" />
  </joint>
  <link
    name="Link_Ankle_D">
    <inertial>
      <origin
        xyz="0.0396103017376912 0.00270429448791487 0.395868736059361"
        rpy="0 0 0" />
      <mass
        value="0.184605421069194" />
      <inertia
        ixx="4.34030510364001E-05"
        ixy="-3.54476065730418E-06"
        ixz="-1.48994605727124E-05"
        iyy="0.0004953347056734"
        iyz="5.99822899610163E-08"
        izz="0.000521624460728874" />
    </inertial>
    <visual>
      <origin
        xyz="0 0 0"
        rpy="0 0 0" />
      <geometry>
        <mesh
          filename="package://Ros2_RobotBipede/meshes/Link_Ankle_D.STL" />
      </geometry>
      <material
        name="">
        <color
          rgba="0.752941176470588 0 0.752941176470588 1" />
      </material>
    </visual>
    <collision>
      <origin
        xyz="0 0 0"
        rpy="0 0 0" />
      <geometry>
        <mesh
          filename="package://Ros2_RobotBipede/meshes/Link_Ankle_D.STL" />
      </geometry>
    </collision>
  </link>
  <joint
    name="Joint_Ankle_D"
    type="revolute">
    <origin
      xyz="0.23881 0.023881 0.0635"
      rpy="0 0 0.14261" />
    <parent
      link="Link_Knee_D" />
    <child
      link="Link_Ankle_D" />
    <axis
      xyz="0 0 -1" />
    <limit
      lower="-3.1415"
      upper="0"
      effort="0"
      velocity="0" />
  </joint>
  <link
    name="Link_Foot_D">
    <inertial>
      <origin
        xyz="-0.024183614586474 0.00472900535085019 0.39236385931783"
        rpy="0 0 0" />
      <mass
        value="0.0546943099715329" />
      <inertia
        ixx="1.34777038749873E-05"
        ixy="1.59485905922863E-06"
        ixz="-1.92965520633829E-07"
        iyy="2.55476090841959E-05"
        iyz="2.18131157553196E-08"
        izz="3.15296344140971E-05" />
    </inertial>
    <visual>
      <origin
        xyz="0 0 0"
        rpy="0 0 0" />
      <geometry>
        <mesh
          filename="package://Ros2_RobotBipede/meshes/Link_Foot_D.STL" />
      </geometry>
      <material
        name="">
        <color
          rgba="0.250980392156863 0.250980392156863 0.250980392156863 1" />
      </material>
    </visual>
    <collision>
      <origin
        xyz="0 0 0"
        rpy="0 0 0" />
      <geometry>
        <mesh
          filename="package://Ros2_RobotBipede/meshes/Link_Foot_D.STL" />
      </geometry>
    </collision>
  </link>
  <joint
    name="Joint_Foot_D"
    type="revolute">
    <origin
      xyz="0.12 0 0.01"
      rpy="0 0 -1.5708" />
    <parent
      link="Link_Ankle_D" />
    <child
      link="Link_Foot_D" />
    <axis
      xyz="0 0 1" />
    <limit
      lower="0"
      upper="3.1415"
      effort="0"
      velocity="0" />
  </joint>
  <link
    name="Link_PalmeD_g">
    <inertial>
      <origin
        xyz="0.00752427478471418 -0.0288252517174629 -0.0416337378484336"
        rpy="0 0 0" />
      <mass
        value="0.0807463947610813" />
      <inertia
        ixx="0.000104013520420242"
        ixy="7.09548939607373E-06"
        ixz="-4.13409053563053E-06"
        iyy="7.84418920096679E-05"
        iyz="1.588878434715E-05"
        izz="3.23075735723034E-05" />
    </inertial>
    <visual>
      <origin
        xyz="0 0 0"
        rpy="0 0 0" />
      <geometry>
        <mesh
          filename="package://Ros2_RobotBipede/meshes/Link_PalmeD_g.STL" />
      </geometry>
      <material
        name="">
        <color
          rgba="1 1 0 1" />
      </material>
    </visual>
    <collision>
      <origin
        xyz="0 0 0"
        rpy="0 0 0" />
      <geometry>
        <mesh
          filename="package://Ros2_RobotBipede/meshes/Link_PalmeD_g.STL" />
      </geometry>
    </collision>
  </link>
  <joint
    name="Joint_PalmeD_g"
    type="revolute">
    <origin
      xyz="-0.13819 0.038047 0.39515"
      rpy="1.5821 0.31937 -1.5945" />
    <parent
      link="Link_Foot_D" />
    <child
      link="Link_PalmeD_g" />
    <axis
      xyz="0 0 -1" />
    <limit
      lower="-1.5707"
      upper="1.5707"
      effort="0"
      velocity="0" />
  </joint>
  <link
    name="Link_PalmeD_d">
    <inertial>
      <origin
        xyz="-0.0122351374798444 0.0271626813559712 -0.0448993183015995"
        rpy="0 0 0" />
      <mass
        value="0.0807463947610811" />
      <inertia
        ixx="0.000107149417523528"
        ixy="1.09121509241879E-05"
        ixz="9.78551104026665E-06"
        iyy="8.76817030331559E-05"
        iyz="-2.18506395767271E-05"
        izz="3.23075735723034E-05" />
    </inertial>
    <visual>
      <origin
        xyz="0 0 0"
        rpy="0 0 0" />
      <geometry>
        <mesh
          filename="package://Ros2_RobotBipede/meshes/Link_PalmeD_d.STL" />
      </geometry>
      <material
        name="">
        <color
          rgba="1 1 0 1" />
      </material>
    </visual>
    <collision>
      <origin
        xyz="0 0 0"
        rpy="0 0 0" />
      <geometry>
        <mesh
          filename="package://Ros2_RobotBipede/meshes/Link_PalmeD_d.STL" />
      </geometry>
    </collision>
  </link>
  <joint
    name="Joint_PalmeD_d"
    type="revolute">
    <origin
      xyz="-0.13819 0.038047 0.39515"
      rpy="1.5821 0.31937 -1.5945" />
    <parent
      link="Link_Foot_D" />
    <child
      link="Link_PalmeD_d" />
    <axis
      xyz="0 0 -1" />
    <limit
      lower="-1.5707"
      upper="1.5707"
      effort="0"
      velocity="0" />
  </joint>
  <link
    name="Link_HipYaw_G">
    <inertial>
      <origin
        xyz="-9.14920620759263E-06 0.0297164013094371 0.0727528311241241"
        rpy="0 0 0" />
      <mass
        value="0.950205196909706" />
      <inertia
        ixx="0.000888067370319887"
        ixy="-3.10038797876888E-07"
        ixz="-7.28258366177286E-07"
        iyy="0.00130826965929317"
        iyz="-1.73990365620638E-05"
        izz="0.000919223484374397" />
    </inertial>
    <visual>
      <origin
        xyz="0 0 0"
        rpy="0 0 0" />
      <geometry>
        <mesh
          filename="package://Ros2_RobotBipede/meshes/Link_HipYaw_G.STL" />
      </geometry>
      <material
        name="">
        <color
          rgba="0.792156862745098 0.819607843137255 0.933333333333333 1" />
      </material>
    </visual>
    <collision>
      <origin
        xyz="0 0 0"
        rpy="0 0 0" />
      <geometry>
        <mesh
          filename="package://Ros2_RobotBipede/meshes/Link_HipYaw_G.STL" />
      </geometry>
    </collision>
  </link>
  <joint
    name="Joint_HipYaw_G"
    type="revolute">
    <origin
      xyz="-0.011806 0.057746 0.1075"
      rpy="0.092261 0 -0.055652" />
    <parent
      link="base_link" />
    <child
      link="Link_HipYaw_G" />
    <axis
      xyz="0 0.09213 0.99575" />
    <limit
      lower="-0.5236"
      upper="0.5236"
      effort="0"
      velocity="0" />
    <safety_controller
      k_position="1"
      k_velocity="1" />
  </joint>
  <link
    name="Link_HipPitch_G">
    <inertial>
      <origin
        xyz="0.000154019260506733 0.00299951106996221 -0.457289702584565"
        rpy="0 0 0" />
      <mass
        value="1.95579685025705" />
      <inertia
        ixx="0.00184767496472383"
        ixy="-0.000291523209074059"
        ixz="0.00109025011266845"
        iyy="0.0113948969015732"
        iyz="1.79130632594967E-05"
        izz="0.0124987422515525" />
    </inertial>
    <visual>
      <origin
        xyz="0 0 0"
        rpy="0 0 0" />
      <geometry>
        <mesh
          filename="package://Ros2_RobotBipede/meshes/Link_HipPitch_G.STL" />
      </geometry>
      <material
        name="">
        <color
          rgba="0.792156862745098 0.819607843137255 0.933333333333333 1" />
      </material>
    </visual>
    <collision>
      <origin
        xyz="0 0 0"
        rpy="0 0 0" />
      <geometry>
        <mesh
          filename="package://Ros2_RobotBipede/meshes/Link_HipPitch_G.STL" />
      </geometry>
    </collision>
  </link>
  <joint
    name="Joint_HipPitch_G"
    type="revolute">
    <origin
      xyz="0.0024054 -0.29102 0.10526"
      rpy="0.092426 1.4781 -1.465" />
    <parent
      link="Link_HipYaw_G" />
    <child
      link="Link_HipPitch_G" />
    <axis
      xyz="0 0 1" />
    <limit
      lower="-1.5707"
      upper="0"
      effort="0"
      velocity="0" />
  </joint>
  <link
    name="Link_Knee_G">
    <inertial>
      <origin
        xyz="0.136087501996235 -0.00914771609014348 -0.519295791416989"
        rpy="0 0 0" />
      <mass
        value="0.315635651588115" />
      <inertia
        ixx="0.00025592480761019"
        ixy="0.000357967850971516"
        ixz="-0.000314521963263219"
        iyy="0.00309087580142431"
        iyz="3.84434445421098E-05"
        izz="0.00316201818502919" />
    </inertial>
    <visual>
      <origin
        xyz="0 0 0"
        rpy="0 0 0" />
      <geometry>
        <mesh
          filename="package://Ros2_RobotBipede/meshes/Link_Knee_G.STL" />
      </geometry>
      <material
        name="">
        <color
          rgba="0 1 1 1" />
      </material>
    </visual>
    <collision>
      <origin
        xyz="0 0 0"
        rpy="0 0 0" />
      <geometry>
        <mesh
          filename="package://Ros2_RobotBipede/meshes/Link_Knee_G.STL" />
      </geometry>
    </collision>
  </link>
  <joint
    name="Joint_Knee_G"
    type="revolute">
    <origin
      xyz="0.16 0 0.0245"
      rpy="0 0 0.051517" />
    <parent
      link="Link_HipPitch_G" />
    <child
      link="Link_Knee_G" />
    <axis
      xyz="0 0 1" />
    <limit
      lower="0"
      upper="3.1415"
      effort="0"
      velocity="0" />
  </joint>
  <link
    name="Link_Ankle_G">
    <inertial>
      <origin
        xyz="0.0397500975639473 0.0006753838731271 -0.396142668899675"
        rpy="0 0 0" />
      <mass
        value="0.186472961115324" />
      <inertia
        ixx="4.63158595208964E-05"
        ixy="2.93208629453237E-06"
        ixz="2.0362420251007E-05"
        iyy="0.000509907707730688"
        iyz="-1.29581081342544E-07"
        izz="0.000534225847487257" />
    </inertial>
    <visual>
      <origin
        xyz="0 0 0"
        rpy="0 0 0" />
      <geometry>
        <mesh
          filename="package://Ros2_RobotBipede/meshes/Link_Ankle_G.STL" />
      </geometry>
      <material
        name="">
        <color
          rgba="0.752941176470588 0 0.752941176470588 1" />
      </material>
    </visual>
    <collision>
      <origin
        xyz="0 0 0"
        rpy="0 0 0" />
      <geometry>
        <mesh
          filename="package://Ros2_RobotBipede/meshes/Link_Ankle_G.STL" />
      </geometry>
    </collision>
  </link>
  <joint
    name="Joint_Ankle_G"
    type="revolute">
    <origin
      xyz="0.23881 -0.023881 -0.0635"
      rpy="0 0 -0.072242" />
    <parent
      link="Link_Knee_G" />
    <child
      link="Link_Ankle_G" />
    <axis
      xyz="0 0 1" />
    <limit
      lower="-3.1415"
      upper="0"
      effort="0"
      velocity="0" />
  </joint>
  <link
    name="Link_Foot_G">
    <inertial>
      <origin
        xyz="-0.0212783620564291 0.00366434320182152 -0.402876501511627"
        rpy="0 0 0" />
      <mass
        value="0.0546943093522807" />
      <inertia
        ixx="1.34225794951054E-05"
        ixy="1.36942907248865E-06"
        ixz="1.93923311439125E-07"
        iyy="2.56027511558376E-05"
        iyz="-8.07752766775745E-09"
        izz="3.152961663084E-05" />
    </inertial>
    <visual>
      <origin
        xyz="0 0 0"
        rpy="0 0 0" />
      <geometry>
        <mesh
          filename="package://Ros2_RobotBipede/meshes/Link_Foot_G.STL" />
      </geometry>
      <material
        name="">
        <color
          rgba="0.250980392156863 0.250980392156863 0.250980392156863 1" />
      </material>
    </visual>
    <collision>
      <origin
        xyz="0 0 0"
        rpy="0 0 0" />
      <geometry>
        <mesh
          filename="package://Ros2_RobotBipede/meshes/Link_Foot_G.STL" />
      </geometry>
    </collision>
  </link>
  <joint
    name="Joint_Foot_G"
    type="revolute">
    <origin
      xyz="0.12 0 0"
      rpy="0 0 -1.5708" />
    <parent
      link="Link_Ankle_G" />
    <child
      link="Link_Foot_G" />
    <axis
      xyz="0 0 1" />
    <limit
      lower="0"
      upper="3.1415"
      effort="0"
      velocity="0" />
  </joint>
  <link
    name="Link_PalmeG_g">
    <inertial>
      <origin
        xyz="-0.0053948926506362 -0.0292985491262852 -0.0416337378491805"
        rpy="0 0 0" />
      <mass
        value="0.080746394761081" />
      <inertia
        ixx="0.000104870221197031"
        ixy="-5.26353489831E-06"
        ixz="2.9858327019749E-06"
        iyy="7.75851912328781E-05"
        iyz="1.61440074226582E-05"
        izz="3.23075735723034E-05" />
    </inertial>
    <visual>
      <origin
        xyz="0 0 0"
        rpy="0 0 0" />
      <geometry>
        <mesh
          filename="package://Ros2_RobotBipede/meshes/Link_PalmeG_g.STL" />
      </geometry>
      <material
        name="">
        <color
          rgba="1 1 0 1" />
      </material>
    </visual>
    <collision>
      <origin
        xyz="0 0 0"
        rpy="0 0 0" />
      <geometry>
        <mesh
          filename="package://Ros2_RobotBipede/meshes/Link_PalmeG_g.STL" />
      </geometry>
    </collision>
  </link>
  <joint
    name="Joint_PalmeG_g"
    type="revolute">
    <origin
      xyz="-0.13588 0.034908 -0.40566"
      rpy="1.56 -0.086323 -1.5785" />
    <parent
      link="Link_Foot_G" />
    <child
      link="Link_PalmeG_g" />
    <axis
      xyz="0 0 -1" />
    <limit
      lower="-1.5707"
      upper="1.5707"
      effort="0"
      velocity="0" />
  </joint>
  <link
    name="Link_PalmeG_d">
    <inertial>
      <origin
        xyz="-0.000167854281118984 0.0297906306165989 -0.0448993183017021"
        rpy="0 0 0" />
      <mass
        value="0.0807463947610813" />
      <inertia
        ixx="0.000112037865588735"
        ixy="1.05839839290183E-07"
        ixz="8.30407929665023E-08"
        iyy="8.27932549679495E-05"
        iyz="-2.39415910176814E-05"
        izz="3.23075735723034E-05" />
    </inertial>
    <visual>
      <origin
        xyz="0 0 0"
        rpy="0 0 0" />
      <geometry>
        <mesh
          filename="package://Ros2_RobotBipede/meshes/Link_PalmeG_d.STL" />
      </geometry>
      <material
        name="">
        <color
          rgba="1 1 0 1" />
      </material>
    </visual>
    <collision>
      <origin
        xyz="0 0 0"
        rpy="0 0 0" />
      <geometry>
        <mesh
          filename="package://Ros2_RobotBipede/meshes/Link_PalmeG_d.STL" />
      </geometry>
    </collision>
  </link>
  <joint
    name="Joint_PalmeG_d"
    type="revolute">
    <origin
      xyz="-0.13588 0.034908 -0.40566"
      rpy="1.56 -0.086323 -1.5785" />
    <parent
      link="Link_Foot_G" />
    <child
      link="Link_PalmeG_d" />
    <axis
      xyz="0 0 -1" />
    <limit
      lower="-1.5707"
      upper="1.5707"
      effort="0"
      velocity="0" />
  </joint>
</robot>